<?xml version="1.0" ?>
<!-- =================================================================================== -->
<!-- |    This document was autogenerated by xacro from diffbot_2wheel.xacro           | -->
<!-- |    EDITING THIS FILE BY HAND IS NOT RECOMMENDED                                 | -->
<!-- =================================================================================== -->
<robot name="diffbot_2wheel">
  <!-- Hokuyo Laser -->
  <!--erratic_hokuyo_laser parent="base_link"> 
    <origin xyz="0.0 0.0 0.0381" rpy="0 0 0"/> 
</erratic_hokuyo_laser-->
  <!--Base Link-->
  <link name="base_link"/>
  <joint name="base_to_chassis" type="fixed">
    <parent link="base_link"/>
    <child link="chassis_link"/>
    <origin rpy="0 0 0" xyz="0 0 0"/>
    <axis xyz="0 0 0"/>
  </joint>
  <!--Chassis Link-->
  <link name="chassis_link">
    <inertial>
      <mass value="1.3"/>
      <inertia ixx="0.006382316704427083" ixy="0" ixz="0" iyy="0.0014570913398437501" iyz="0" izz="0.007524892544270834"/>
    </inertial>
    <collision name="base_link_collision">
      <geometry>
        <box size="0.2397125 0.1095375 0.0381"/>
      </geometry>
    </collision>
    <visual>
      <geometry>
        <box size="0.2397125 0.1095375 0.0381"/>
      </geometry>
      <material name="orange">
        <color rgba="1 0.647 0 1"/>
      </material>
    </visual>
  </link>
  <gazebo reference="chassis_link">
    <material>Gazebo/Orange</material>
  </gazebo>
  <!--Rear Caster-->
  <link name="caster_link">
    <collision name="caster_collision">
      <origin rpy="0 0 0" xyz="0 0 0"/>
      <geometry>
        <cylinder length="0.0254" radius="0.03175"/>
      </geometry>
    </collision>
    <visual>
      <origin rpy="0 0 0" xyz="0 0 0"/>
      <geometry>
        <cylinder length="0.0254" radius="0.03175"/>
      </geometry>
      <material name="grey">
        <color rgba="0.392 0.392 0.392 1"/>
      </material>
    </visual>
  </link>
  <joint name="caster_joint" type="fixed">
    <parent link="base_link"/>
    <child link="caster_link"/>
    <origin rpy="1.5707963267948966 0 0" xyz="-0.059928125 0 0"/>
    <axis xyz="0 0 0"/>
  </joint>
  <gazebo reference="caster_link">
    <material>Gazebo/Grey</material>
  </gazebo>
  <!--Right Wheel-->
  <link name="right_wheel">
    <inertial>
      <mass value="0.0283495"/>
      <inertia ixx="8.668680579270833e-06" ixy="0" ixz="0" iyy="8.668680579270833e-06" iyz="0" izz="1.4289033921875e-05"/>
    </inertial>
    <collision>
      <origin rpy="0 0 0" xyz="0 0 0"/>
      <geometry>
        <cylinder length="0.0254" radius="0.03175"/>
      </geometry>
    </collision>
    <visual>
      <origin rpy="0 0 0" xyz="0 0 0"/>
      <geometry>
        <cylinder length="0.0254" radius="0.03175"/>
      </geometry>
      <material name="black">
        <color rgba="0 0 0 1"/>
      </material>
    </visual>
  </link>
  <joint name="joint_right_wheel" type="continuous">
    <parent link="base_link"/>
    <child link="right_wheel"/>
    <origin rpy="1.5707963267948966 0 0" xyz="0.059928125 0.06746875 0"/>
    <axis xyz="0 0 -1"/>
  </joint>
  <gazebo reference="right_wheel">
    <material>Gazebo/Black</material>
  </gazebo>
  <!--Left Wheel-->
  <link name="left_wheel">
    <inertial>
      <mass value="0.0283495"/>
      <inertia ixx="8.668680579270833e-06" ixy="0" ixz="0" iyy="8.668680579270833e-06" iyz="0" izz="1.4289033921875e-05"/>
    </inertial>
    <collision>
      <origin rpy="0 0 0" xyz="0 0 0"/>
      <geometry>
        <cylinder length="0.0254" radius="0.03175"/>
      </geometry>
    </collision>
    <visual>
      <origin rpy="0 0 0" xyz="0 0 0"/>
      <geometry>
        <cylinder length="0.0254" radius="0.03175"/>
      </geometry>
      <material name="black">
        <color rgba="0 0 0 1"/>
      </material>
    </visual>
  </link>
  <joint name="joint_left_wheel" type="continuous">
    <parent link="base_link"/>
    <child link="left_wheel"/>
    <origin rpy="1.5707963267948966 0 0" xyz="0.059928125 -0.06746875 0"/>
    <axis xyz="0 0 1"/>
  </joint>
  <gazebo reference="left_wheel">
    <material>Gazebo/Black</material>
  </gazebo>
</robot>

