<?xml version="1.0" ?>
<!-- =================================================================================== -->
<!-- |    This document was autogenerated by xacro from diffbot_2wheel.xacro           | -->
<!-- |    EDITING THIS FILE BY HAND IS NOT RECOMMENDED                                 | -->
<!-- =================================================================================== -->
<robot name="diffbot_2wheel">
  <!-- Hokuyo Laser -->
  <link name="hokuyo_link">
    <collision>
      <origin rpy="0 0 0" xyz="0 0 0"/>
      <geometry>
        <box size="0.1 0.1 0.1"/>
      </geometry>
    </collision>
    <visual>
      <origin rpy="0 0 0" xyz="0 0 0"/>
      <geometry>
        <!--Mesh obtained from  https://github.com/ros-simulation/gazebo_ros_demos-->
        <mesh filename="package://diffbot_1/meshes/hokuyo.dae"/>
      </geometry>
    </visual>
    <inertial>
      <mass value="1e-5"/>
      <origin rpy="0 0 0" xyz="0 0 0"/>
      <inertia ixx="1e-6" ixy="0" ixz="0" iyy="1e-6" iyz="0" izz="1e-6"/>
    </inertial>
  </link>
  <joint name="hokuyo_joint" type="fixed">
    <axis xyz="0 1 0"/>
    <origin rpy="0 0 0" xyz="0.059928125 0 0.0381"/>
    <parent link="base_link"/>
    <child link="hokuyo_link"/>
  </joint>
  <!-- Gazebo Hokuyo -->
  <gazebo reference="hokuyo_link">
    <sensor name="head_hokuyo_sensor" type="gpu_ray">
      <pose>0 0 0 0 0 0</pose>
      <visualize>false</visualize>
      <update_rate>40</update_rate>
      <ray>
        <scan>
          <horizontal>
            <samples>720</samples>
            <resolution>1</resolution>
            <min_angle>-1.570796</min_angle>
            <max_angle>1.570796</max_angle>
          </horizontal>
        </scan>
        <range>
          <min>0.10</min>
          <max>30.0</max>
          <resolution>0.01</resolution>
        </range>
        <noise>
          <type>gaussian</type>
          <!-- Noise parameters based on published spec for Hokuyo laser achieving 
                        "+-30mm" accuracy at range < 10m. A mean of 0.0m and stddev of 0.01m will 
                        put 99.7% of samples within 0.03m of the true reading. -->
          <mean>0.0</mean>
          <stddev>0.01</stddev>
        </noise>
      </ray>
      <plugin filename="libgazebo_ros_gpu_laser.so" name="gazebo_ros_head_hokuyo_controller">
        <topicName>/rrbot/laser/scan</topicName>
        <frameName>hokuyo_link</frameName>
      </plugin>
    </sensor>
  </gazebo>
  <!--Base Link-->
  <link name="base_link"/>
  <joint name="base_to_chassis" type="fixed">
    <parent link="base_link"/>
    <child link="chassis_link"/>
    <origin rpy="0 0 0" xyz="0 0 0"/>
    <axis xyz="0 0 0"/>
  </joint>
  <!--Chassis Link-->
  <link name="chassis_link">
    <inertial>
      <mass value="1.3"/>
      <inertia ixx="0.006382316704427083" ixy="0" ixz="0" iyy="0.0014570913398437501" iyz="0" izz="0.007524892544270834"/>
    </inertial>
    <collision name="base_link_collision">
      <geometry>
        <box size="0.2397125 0.1095375 0.0381"/>
      </geometry>
    </collision>
    <visual>
      <geometry>
        <box size="0.2397125 0.1095375 0.0381"/>
      </geometry>
      <material name="orange">
        <color rgba="1 0.647 0 1"/>
      </material>
    </visual>
  </link>
  <gazebo reference="chassis_link">
    <material>Gazebo/Orange</material>
  </gazebo>
  <!--Rear Caster-->
  <link name="caster_link">
    <collision name="caster_collision">
      <origin rpy="0 0 0" xyz="0 0 0"/>
      <geometry>
        <cylinder length="0.0254" radius="0.03175"/>
      </geometry>
    </collision>
    <visual>
      <origin rpy="0 0 0" xyz="0 0 0"/>
      <geometry>
        <cylinder length="0.0254" radius="0.03175"/>
      </geometry>
      <material name="grey">
        <color rgba="0.392 0.392 0.392 1"/>
      </material>
    </visual>
  </link>
  <joint name="caster_joint" type="fixed">
    <parent link="base_link"/>
    <child link="caster_link"/>
    <origin rpy="1.5707963267948966 0 0" xyz="-0.059928125 0 0"/>
    <axis xyz="0 0 0"/>
  </joint>
  <gazebo reference="caster_link">
    <material>Gazebo/Grey</material>
  </gazebo>
  <!--Right Wheel-->
  <link name="right_wheel">
    <inertial>
      <mass value="0.0283495"/>
      <inertia ixx="8.668680579270833e-06" ixy="0" ixz="0" iyy="8.668680579270833e-06" iyz="0" izz="1.4289033921875e-05"/>
    </inertial>
    <collision>
      <origin rpy="0 0 0" xyz="0 0 0"/>
      <geometry>
        <cylinder length="0.0254" radius="0.03175"/>
      </geometry>
    </collision>
    <visual>
      <origin rpy="0 0 0" xyz="0 0 0"/>
      <geometry>
        <cylinder length="0.0254" radius="0.03175"/>
      </geometry>
      <material name="black">
        <color rgba="0 0 0 1"/>
      </material>
    </visual>
  </link>
  <joint name="joint_right_wheel" type="continuous">
    <parent link="base_link"/>
    <child link="right_wheel"/>
    <origin rpy="1.5707963267948966 0 0" xyz="0.059928125 0.06746875 0"/>
    <axis xyz="0 0 -1"/>
  </joint>
  <gazebo reference="right_wheel">
    <material>Gazebo/Black</material>
  </gazebo>
  <!--Left Wheel-->
  <link name="left_wheel">
    <inertial>
      <mass value="0.0283495"/>
      <inertia ixx="8.668680579270833e-06" ixy="0" ixz="0" iyy="8.668680579270833e-06" iyz="0" izz="1.4289033921875e-05"/>
    </inertial>
    <collision>
      <origin rpy="0 0 0" xyz="0 0 0"/>
      <geometry>
        <cylinder length="0.0254" radius="0.03175"/>
      </geometry>
    </collision>
    <visual>
      <origin rpy="0 0 0" xyz="0 0 0"/>
      <geometry>
        <cylinder length="0.0254" radius="0.03175"/>
      </geometry>
      <material name="black">
        <color rgba="0 0 0 1"/>
      </material>
    </visual>
  </link>
  <joint name="joint_left_wheel" type="continuous">
    <parent link="base_link"/>
    <child link="left_wheel"/>
    <origin rpy="1.5707963267948966 0 0" xyz="0.059928125 -0.06746875 0"/>
    <axis xyz="0 0 1"/>
  </joint>
  <gazebo reference="left_wheel">
    <material>Gazebo/Black</material>
  </gazebo>
</robot>

