<?xml version="1.0" ?>
<!-- =================================================================================== -->
<!-- |    This document was autogenerated by xacro from diffbot_4wheel.xacro           | -->
<!-- |    EDITING THIS FILE BY HAND IS NOT RECOMMENDED                                 | -->
<!-- =================================================================================== -->
<robot name="diffbot_4wheel">
  <!-- Hokuyo Laser -->
  <link name="hokuyo_link">
    <collision>
      <origin rpy="0 0 0" xyz="0 0 0"/>
      <geometry>
        <box size="0.1 0.1 0.1"/>
      </geometry>
    </collision>
    <visual>
      <origin rpy="0 0 0" xyz="0 0 0"/>
      <geometry>
        <!--Mesh obtained from  https://github.com/ros-simulation/gazebo_ros_demos-->
        <mesh filename="package://diffbot_1/meshes/hokuyo.dae"/>
      </geometry>
    </visual>
    <inertial>
      <mass value="1e-5"/>
      <origin rpy="0 0 0" xyz="0 0 0"/>
      <inertia ixx="1e-6" ixy="0" ixz="0" iyy="1e-6" iyz="0" izz="1e-6"/>
    </inertial>
  </link>
  <joint name="hokuyo_joint" type="fixed">
    <axis xyz="0 1 0"/>
    <origin rpy="0 0 0" xyz="0 0 0.0492125"/>
    <parent link="base_link"/>
    <child link="hokuyo_link"/>
  </joint>
  <!-- Gazebo Hokuyo -->
  <gazebo reference="hokuyo_link">
    <sensor name="head_hokuyo_sensor" type="gpu_ray">
      <pose>0 0 0 0 0 0</pose>
      <visualize>false</visualize>
      <update_rate>40</update_rate>
      <ray>
        <scan>
          <horizontal>
            <samples>720</samples>
            <resolution>1</resolution>
            <min_angle>-1.570796</min_angle>
            <max_angle>1.570796</max_angle>
          </horizontal>
        </scan>
        <range>
          <min>0.10</min>
          <max>30.0</max>
          <resolution>0.01</resolution>
        </range>
        <noise>
          <type>gaussian</type>
          <!-- Noise parameters based on published spec for Hokuyo laser achieving 
                        "+-30mm" accuracy at range < 10m. A mean of 0.0m and stddev of 0.01m will 
                        put 99.7% of samples within 0.03m of the true reading. -->
          <mean>0.0</mean>
          <stddev>0.01</stddev>
        </noise>
      </ray>
      <plugin filename="libgazebo_ros_gpu_laser.so" name="gazebo_ros_head_hokuyo_controller">
        <topicName>/rrbot/laser/scan</topicName>
        <frameName>hokuyo_link</frameName>
      </plugin>
    </sensor>
  </gazebo>
  <!--Base Link-->
  <link name="base_link"/>
  <joint name="base_to_chassis" type="fixed">
    <parent link="base_link"/>
    <child link="chassis_link"/>
    <origin rpy="0 0 0" xyz="0 0 0"/>
    <axis xyz="0 0 0"/>
  </joint>
  <!--Chassis Link-->
  <link name="chassis_link">
    <inertial>
      <mass value="1.5"/>
      <inertia ixx="0.006926019414062499" ixy="0" ixz="0" iyy="0.0013993167578124999" iyz="0" izz="0.007719868632812499"/>
    </inertial>
    <collision name="base_link_collision">
      <origin rpy="0 0 0" xyz="0 0 0"/>
      <geometry>
        <box size="0.2301875 0.0936625 0.0492125"/>
      </geometry>
    </collision>
    <visual>
      <origin rpy="0 0 0" xyz="0 0 0"/>
      <geometry>
        <box size="0.2301875 0.0936625 0.0492125"/>
      </geometry>
      <material name="bright_green">
        <color rgba="0 1 0 1"/>
      </material>
    </visual>
  </link>
  <gazebo reference="chassis_link">
    <material>Gazebo/Green</material>
  </gazebo>
  <!--Front Right Wheel-->
  <link name="front_right_wheel">
    <inertial>
      <mass value="0.0283495"/>
      <inertia ixx="8.668680579270833e-06" ixy="0" ixz="0" iyy="8.668680579270833e-06" iyz="0" izz="1.4289033921875e-05"/>
    </inertial>
    <collision>
      <origin rpy="0 0 0" xyz="0 0 0"/>
      <geometry>
        <cylinder length="0.0254" radius="0.03175"/>
      </geometry>
    </collision>
    <visual>
      <origin rpy="0 0 0" xyz="0 0 0"/>
      <geometry>
        <cylinder length="0.0254" radius="0.03175"/>
      </geometry>
      <material name="black">
        <color rgba="0 0 0 1"/>
      </material>
    </visual>
  </link>
  <joint name="joint_front_right_wheel" type="continuous">
    <parent link="base_link"/>
    <child link="front_right_wheel"/>
    <origin rpy="1.5707963267948966 0 0" xyz="0.057546875 0.059531249999999994 0"/>
    <axis xyz="0 0 -1"/>
  </joint>
  <gazebo reference="front_right_wheel">
    <material>Gazebo/Black</material>
  </gazebo>
  <!--Front Left Wheel-->
  <link name="front_left_wheel">
    <inertial>
      <mass value="0.0283495"/>
      <inertia ixx="8.668680579270833e-06" ixy="0" ixz="0" iyy="8.668680579270833e-06" iyz="0" izz="1.4289033921875e-05"/>
    </inertial>
    <collision>
      <origin rpy="0 0 0" xyz="0 0 0"/>
      <geometry>
        <cylinder length="0.0254" radius="0.03175"/>
      </geometry>
    </collision>
    <visual>
      <origin rpy="0 0 0" xyz="0 0 0"/>
      <geometry>
        <cylinder length="0.0254" radius="0.03175"/>
      </geometry>
      <material name="black">
        <color rgba="0 0 0 1"/>
      </material>
    </visual>
  </link>
  <joint name="joint_front_left_wheel" type="continuous">
    <parent link="base_link"/>
    <child link="front_left_wheel"/>
    <origin rpy="-1.5707963267948966 0 0" xyz="0.057546875 -0.059531249999999994 0"/>
    <axis xyz="0 0 1"/>
  </joint>
  <gazebo reference="front_left_wheel">
    <material>Gazebo/Black</material>
  </gazebo>
  <!--Back Right Wheel-->
  <link name="back_right_wheel">
    <inertial>
      <mass value="0.0283495"/>
      <inertia ixx="8.668680579270833e-06" ixy="0" ixz="0" iyy="8.668680579270833e-06" iyz="0" izz="1.4289033921875e-05"/>
    </inertial>
    <collision>
      <origin rpy="0 0 0" xyz="0 0 0"/>
      <geometry>
        <cylinder length="0.0254" radius="0.03175"/>
      </geometry>
    </collision>
    <visual>
      <origin rpy="0 0 0" xyz="0 0 0"/>
      <geometry>
        <cylinder length="0.0254" radius="0.03175"/>
      </geometry>
      <material name="black">
        <color rgba="0 0 0 1"/>
      </material>
    </visual>
  </link>
  <joint name="joint_back_right_wheel" type="continuous">
    <parent link="base_link"/>
    <child link="back_right_wheel"/>
    <origin rpy="1.5707963267948966 0 0" xyz="-0.057546875 0.059531249999999994 0"/>
    <axis xyz="0 0 -1"/>
  </joint>
  <gazebo reference="back_right_wheel">
    <material>Gazebo/Black</material>
  </gazebo>
  <!--Back Left Wheel-->
  <link name="back_left_wheel">
    <inertial>
      <mass value="0.0283495"/>
      <inertia ixx="8.668680579270833e-06" ixy="0" ixz="0" iyy="8.668680579270833e-06" iyz="0" izz="1.4289033921875e-05"/>
    </inertial>
    <collision>
      <origin rpy="0 0 0" xyz="0 0 0"/>
      <geometry>
        <cylinder length="0.0254" radius="0.03175"/>
      </geometry>
    </collision>
    <visual>
      <origin rpy="0 0 0" xyz="0 0 0"/>
      <geometry>
        <cylinder length="0.0254" radius="0.03175"/>
      </geometry>
      <material name="black">
        <color rgba="0 0 0 1"/>
      </material>
    </visual>
  </link>
  <joint name="joint_back_left_wheel" type="continuous">
    <parent link="base_link"/>
    <child link="back_left_wheel"/>
    <origin rpy="-1.5707963267948966 0 0" xyz="-0.057546875 -0.059531249999999994 0"/>
    <axis xyz="0 0 1"/>
  </joint>
  <gazebo reference="back_left_wheel">
    <material>Gazebo/Black</material>
  </gazebo>
  <!--Gazebo Plugin-->
  <gazebo>
    <plugin filename="libgazebo_ros_control.so" name="gazebo_ros_control">
      <robotNamespace>/</robotNamespace>
    </plugin>
  </gazebo>
</robot>

