<?xml version="1.0"?>
<robot name="diffbot_2wheel" xmlns:xacro="http://www.ros.org/wiki/xacro">
<include filename="$(find erratic_description)/urdf/erratic_hokuyo_ laser.xacro" /> 
<xacro:property name="wheel_radius" value="0.03175"/>
<xacro:property name="wheel_length" value="0.0254"/>
<xacro:property name="wheel_mass" value="0.0283495"/>
<xacro:property name="wheel_inertial_xx" value="0.000008668680579"/>
<xacro:property name="wheel_inertial_yy" value="0.000008668680579"/>
<xacro:property name="wheel_inertial_zz" value="0.000002381505654"/>
<xacro:property name="wheel_x_pos" value="0.057546875"/>
<xacro:property name="wheel_y_pos" value="0.04683125"/>
<xacro:property name="wheel_z_pos" value="0"/>

<!-- Hokuyo Laser --> 
<erratic_hokuyo_laser parent="base_link"> 
    <origin xyz="0.0 0.0 0.0381" rpy="0 0 0"/> 
</erratic_hokuyo_laser>

<!--Base Link-->  
    <link name="base_link">   
        <inertial>
            <mass value="1.3"/>
            <inertia ixx="0.006382316704" ixy="0" ixz="0"
                    iyy="0.001457091340" iyz="0" izz="0.007524892544"/>
        </inertial>

        <collision name="base_link_collision">
            <geometry>
                <box size="0.2397125 0.1095375 0.0381"/>
            </geometry>
        </collision>
        
        <visual>
            <geometry>
                <box size="0.2397125 0.1095375 0.0381"/>
            </geometry>
            <material name="bright_green">
                <color rgba="0 255 0 1"/>
            </material>
        </visual>

        <!--Rear Caster-->

        <collision name="caster_collision">
            <origin xyz="0 0 0" rpy="0 0 0"/>
            <geometry>
                <cylinder radius="0.0" length="1.0"/>
            </geometry>
        </collision>

        <visual>
            <origin xyz="0 0 0" rpy="0 0 0"/>
            <geometry>
                <cylinder radius="2.5625" length="1.0"/>
            </geometry>
            <material name="bright_green">
                <color rgba="0 255 0 1"/>
            </material>
        </visual>
    </link>

    
<!--Right Wheel--> 
    <link name="right_wheel">
        <inertial>
            <mass value="${wheel_mass}"/>
            <inertia ixx="${wheel_inertial_xx}" ixy="0" ixz="0"
                    iyy="${wheel_inertial_yy}" iyz="0" izz="${wheel_inertial_zz}"/>
        </inertial>

        <collision>
            <origin xyz="0 0 0" rpy="0 0 0"/>
            <geometry>
                <cylinder radius="${wheel_radius}" length="${wheel_length}"/>
            </geometry>
        </collision>

        <visual>
            <origin xyz="0 0 0" rpy="0 0 0"/>
            <geometry>
                <cylinder radius="${wheel_radius}" length="${wheel_length}"/>
            </geometry>
            <material name="black">
                <color rgba="0 0 0 1"/>
            </material>
        </visual>
    </link>

    <joint name="joint_right_wheel" type="continuous">
        <parent link="base_link"/>
        <child link="right_wheel"/>
        <origin xyz="${wheel_x_pos} ${wheel_y_pos} ${wheel_z_pos}" rpy="0 0 0"/>
        <axis xyz="0 1 0"/>
    </joint>

<!--Left Wheel--> 
    <link name="left_wheel">
        <inertial>
            <mass value="${wheel_mass}"/>
            <inertia ixx="${wheel_inertial_xx}" ixy="0" ixz="0"
                    iyy="${wheel_inertial_yy}" iyz="0" izz="${wheel_inertial_zz}"/>
        </inertial>

        <collision>
            <origin xyz="0 0 0" rpy="0 0 0"/>
            <geometry>
                <cylinder radius="${wheel_radius}" length="${wheel_length}"/>
            </geometry>
        </collision>

        <visual>
            <origin xyz="0 0 0" rpy="0 0 0"/>
            <geometry>
                <cylinder radius="${wheel_radius}" length="${wheel_length}"/>
            </geometry>
            <material name="black">
                <color rgba="0 0 0 1"/>
            </material>
        </visual>
    </link>

    <joint name="joint_left_wheel" type="continuous">
        <parent link="base_link"/>
        <child link="left_wheel"/>
        <origin xyz="${wheel_x_pos} -${wheel_y_pos} ${wheel_z_pos}" rpy="0 0 0"/>
        <axis xyz="0 1 0"/>
    </joint>


</robot>
